[ 2023-04-19 07:30:04,557 ] 224 werkzeug - INFO - [31m[1mWARNING: This is a development server. Do not use it in a production deployment. Use a production WSGI server instead.[0m
 * Running on all addresses (0.0.0.0)
 * Running on http://127.0.0.1:5000
 * Running on http://192.168.171.172:5000
[ 2023-04-19 07:30:04,557 ] 224 werkzeug - INFO - [33mPress CTRL+C to quit[0m
[ 2023-04-19 07:30:15,222 ] 224 werkzeug - INFO - 127.0.0.1 - - [19/Apr/2023 07:30:15] "GET / HTTP/1.1" 200 -
[ 2023-04-19 07:30:15,252 ] 224 werkzeug - INFO - 127.0.0.1 - - [19/Apr/2023 07:30:15] "[33mGET /favicon.ico HTTP/1.1[0m" 404 -
[ 2023-04-19 07:30:20,509 ] 224 werkzeug - INFO - 127.0.0.1 - - [19/Apr/2023 07:30:20] "GET /predict HTTP/1.1" 200 -
[ 2023-04-19 07:30:31,318 ] 68 root - INFO - Dataframe Gathered
[ 2023-04-19 07:30:31,521 ] 29 root - INFO - Exception occured in prediction
[ 2023-04-19 07:30:31,521 ] 1744 application - ERROR - Exception on /predict [POST]
Traceback (most recent call last):
  File "C:\pythoncode\Flask_aws\src\pipelines\prediction_pipeline.py", line 22, in predict
    data_scaled=preprocessor.transform(features)
  File "c:\pythoncode\houseprice\venv\lib\site-packages\sklearn\utils\_set_output.py", line 140, in wrapped
    data_to_wrap = f(self, X, *args, **kwargs)
  File "c:\pythoncode\houseprice\venv\lib\site-packages\sklearn\compose\_column_transformer.py", line 800, in transform
    Xs = self._fit_transform(
  File "c:\pythoncode\houseprice\venv\lib\site-packages\sklearn\compose\_column_transformer.py", line 658, in _fit_transform
    return Parallel(n_jobs=self.n_jobs)(
  File "c:\pythoncode\houseprice\venv\lib\site-packages\sklearn\utils\parallel.py", line 63, in __call__
    return super().__call__(iterable_with_config)
  File "c:\pythoncode\houseprice\venv\lib\site-packages\joblib\parallel.py", line 1088, in __call__
    while self.dispatch_one_batch(iterator):
  File "c:\pythoncode\houseprice\venv\lib\site-packages\joblib\parallel.py", line 901, in dispatch_one_batch
    self._dispatch(tasks)
  File "c:\pythoncode\houseprice\venv\lib\site-packages\joblib\parallel.py", line 819, in _dispatch
    job = self._backend.apply_async(batch, callback=cb)
  File "c:\pythoncode\houseprice\venv\lib\site-packages\joblib\_parallel_backends.py", line 208, in apply_async
    result = ImmediateResult(func)
  File "c:\pythoncode\houseprice\venv\lib\site-packages\joblib\_parallel_backends.py", line 597, in __init__
    self.results = batch()
  File "c:\pythoncode\houseprice\venv\lib\site-packages\joblib\parallel.py", line 288, in __call__
    return [func(*args, **kwargs)
  File "c:\pythoncode\houseprice\venv\lib\site-packages\joblib\parallel.py", line 288, in <listcomp>
    return [func(*args, **kwargs)
  File "c:\pythoncode\houseprice\venv\lib\site-packages\sklearn\utils\parallel.py", line 123, in __call__
    return self.function(*args, **kwargs)
  File "c:\pythoncode\houseprice\venv\lib\site-packages\sklearn\pipeline.py", line 876, in _transform_one
    res = transformer.transform(X)
  File "c:\pythoncode\houseprice\venv\lib\site-packages\sklearn\pipeline.py", line 658, in transform
    Xt = transform.transform(Xt)
  File "c:\pythoncode\houseprice\venv\lib\site-packages\sklearn\utils\_set_output.py", line 140, in wrapped
    data_to_wrap = f(self, X, *args, **kwargs)
  File "c:\pythoncode\houseprice\venv\lib\site-packages\sklearn\preprocessing\_encoders.py", line 1378, in transform
    X_int, X_mask = self._transform(
  File "c:\pythoncode\houseprice\venv\lib\site-packages\sklearn\preprocessing\_encoders.py", line 174, in _transform
    raise ValueError(msg)
ValueError: Found unknown categories [('Fair',)] in column 0 during transform

During handling of the above exception, another exception occurred:

Traceback (most recent call last):
  File "c:\pythoncode\houseprice\venv\lib\site-packages\flask\app.py", line 2528, in wsgi_app
    response = self.full_dispatch_request()
  File "c:\pythoncode\houseprice\venv\lib\site-packages\flask\app.py", line 1825, in full_dispatch_request
    rv = self.handle_user_exception(e)
  File "c:\pythoncode\houseprice\venv\lib\site-packages\flask\app.py", line 1823, in full_dispatch_request
    rv = self.dispatch_request()
  File "c:\pythoncode\houseprice\venv\lib\site-packages\flask\app.py", line 1799, in dispatch_request
    return self.ensure_sync(self.view_functions[rule.endpoint])(**view_args)
  File "application.py", line 55, in predict_datapoint
    pred=predict_pipeline.predict(final_df)
  File "C:\pythoncode\Flask_aws\src\pipelines\prediction_pipeline.py", line 30, in predict
    raise CustomException(e,sys)
src.exception.CustomException: Error occured in python script name [C:\pythoncode\Flask_aws\src\pipelines\prediction_pipeline.py] line number [22] error message [Found unknown categories [('Fair',)] in column 0 during transform]
[ 2023-04-19 07:30:31,528 ] 224 werkzeug - INFO - 127.0.0.1 - - [19/Apr/2023 07:30:31] "[35m[1mPOST /predict HTTP/1.1[0m" 500 -
[ 2023-04-19 07:31:52,153 ] 224 werkzeug - INFO - 127.0.0.1 - - [19/Apr/2023 07:31:52] "GET / HTTP/1.1" 200 -
[ 2023-04-19 07:31:55,475 ] 224 werkzeug - INFO - 127.0.0.1 - - [19/Apr/2023 07:31:55] "GET /predict HTTP/1.1" 200 -
[ 2023-04-19 07:32:08,913 ] 68 root - INFO - Dataframe Gathered
[ 2023-04-19 07:32:08,921 ] 29 root - INFO - Exception occured in prediction
[ 2023-04-19 07:32:08,921 ] 1744 application - ERROR - Exception on /predict [POST]
Traceback (most recent call last):
  File "C:\pythoncode\Flask_aws\src\pipelines\prediction_pipeline.py", line 22, in predict
    data_scaled=preprocessor.transform(features)
  File "c:\pythoncode\houseprice\venv\lib\site-packages\sklearn\utils\_set_output.py", line 140, in wrapped
    data_to_wrap = f(self, X, *args, **kwargs)
  File "c:\pythoncode\houseprice\venv\lib\site-packages\sklearn\compose\_column_transformer.py", line 800, in transform
    Xs = self._fit_transform(
  File "c:\pythoncode\houseprice\venv\lib\site-packages\sklearn\compose\_column_transformer.py", line 658, in _fit_transform
    return Parallel(n_jobs=self.n_jobs)(
  File "c:\pythoncode\houseprice\venv\lib\site-packages\sklearn\utils\parallel.py", line 63, in __call__
    return super().__call__(iterable_with_config)
  File "c:\pythoncode\houseprice\venv\lib\site-packages\joblib\parallel.py", line 1088, in __call__
    while self.dispatch_one_batch(iterator):
  File "c:\pythoncode\houseprice\venv\lib\site-packages\joblib\parallel.py", line 901, in dispatch_one_batch
    self._dispatch(tasks)
  File "c:\pythoncode\houseprice\venv\lib\site-packages\joblib\parallel.py", line 819, in _dispatch
    job = self._backend.apply_async(batch, callback=cb)
  File "c:\pythoncode\houseprice\venv\lib\site-packages\joblib\_parallel_backends.py", line 208, in apply_async
    result = ImmediateResult(func)
  File "c:\pythoncode\houseprice\venv\lib\site-packages\joblib\_parallel_backends.py", line 597, in __init__
    self.results = batch()
  File "c:\pythoncode\houseprice\venv\lib\site-packages\joblib\parallel.py", line 288, in __call__
    return [func(*args, **kwargs)
  File "c:\pythoncode\houseprice\venv\lib\site-packages\joblib\parallel.py", line 288, in <listcomp>
    return [func(*args, **kwargs)
  File "c:\pythoncode\houseprice\venv\lib\site-packages\sklearn\utils\parallel.py", line 123, in __call__
    return self.function(*args, **kwargs)
  File "c:\pythoncode\houseprice\venv\lib\site-packages\sklearn\pipeline.py", line 876, in _transform_one
    res = transformer.transform(X)
  File "c:\pythoncode\houseprice\venv\lib\site-packages\sklearn\pipeline.py", line 658, in transform
    Xt = transform.transform(Xt)
  File "c:\pythoncode\houseprice\venv\lib\site-packages\sklearn\utils\_set_output.py", line 140, in wrapped
    data_to_wrap = f(self, X, *args, **kwargs)
  File "c:\pythoncode\houseprice\venv\lib\site-packages\sklearn\preprocessing\_encoders.py", line 1378, in transform
    X_int, X_mask = self._transform(
  File "c:\pythoncode\houseprice\venv\lib\site-packages\sklearn\preprocessing\_encoders.py", line 174, in _transform
    raise ValueError(msg)
ValueError: Found unknown categories [('Good',)] in column 0 during transform

During handling of the above exception, another exception occurred:

Traceback (most recent call last):
  File "c:\pythoncode\houseprice\venv\lib\site-packages\flask\app.py", line 2528, in wsgi_app
    response = self.full_dispatch_request()
  File "c:\pythoncode\houseprice\venv\lib\site-packages\flask\app.py", line 1825, in full_dispatch_request
    rv = self.handle_user_exception(e)
  File "c:\pythoncode\houseprice\venv\lib\site-packages\flask\app.py", line 1823, in full_dispatch_request
    rv = self.dispatch_request()
  File "c:\pythoncode\houseprice\venv\lib\site-packages\flask\app.py", line 1799, in dispatch_request
    return self.ensure_sync(self.view_functions[rule.endpoint])(**view_args)
  File "application.py", line 55, in predict_datapoint
    pred=predict_pipeline.predict(final_df)
  File "C:\pythoncode\Flask_aws\src\pipelines\prediction_pipeline.py", line 30, in predict
    raise CustomException(e,sys)
src.exception.CustomException: Error occured in python script name [C:\pythoncode\Flask_aws\src\pipelines\prediction_pipeline.py] line number [22] error message [Found unknown categories [('Good',)] in column 0 during transform]
[ 2023-04-19 07:32:08,924 ] 224 werkzeug - INFO - 127.0.0.1 - - [19/Apr/2023 07:32:08] "[35m[1mPOST /predict HTTP/1.1[0m" 500 -
[ 2023-04-19 07:36:33,349 ] 224 werkzeug - INFO - 127.0.0.1 - - [19/Apr/2023 07:36:33] "GET /predict HTTP/1.1" 200 -
[ 2023-04-19 07:36:44,008 ] 68 root - INFO - Dataframe Gathered
[ 2023-04-19 07:36:44,012 ] 29 root - INFO - Exception occured in prediction
[ 2023-04-19 07:36:44,012 ] 1744 application - ERROR - Exception on /predict [POST]
Traceback (most recent call last):
  File "C:\pythoncode\Flask_aws\src\pipelines\prediction_pipeline.py", line 22, in predict
    data_scaled=preprocessor.transform(features)
  File "c:\pythoncode\houseprice\venv\lib\site-packages\sklearn\utils\_set_output.py", line 140, in wrapped
    data_to_wrap = f(self, X, *args, **kwargs)
  File "c:\pythoncode\houseprice\venv\lib\site-packages\sklearn\compose\_column_transformer.py", line 800, in transform
    Xs = self._fit_transform(
  File "c:\pythoncode\houseprice\venv\lib\site-packages\sklearn\compose\_column_transformer.py", line 658, in _fit_transform
    return Parallel(n_jobs=self.n_jobs)(
  File "c:\pythoncode\houseprice\venv\lib\site-packages\sklearn\utils\parallel.py", line 63, in __call__
    return super().__call__(iterable_with_config)
  File "c:\pythoncode\houseprice\venv\lib\site-packages\joblib\parallel.py", line 1088, in __call__
    while self.dispatch_one_batch(iterator):
  File "c:\pythoncode\houseprice\venv\lib\site-packages\joblib\parallel.py", line 901, in dispatch_one_batch
    self._dispatch(tasks)
  File "c:\pythoncode\houseprice\venv\lib\site-packages\joblib\parallel.py", line 819, in _dispatch
    job = self._backend.apply_async(batch, callback=cb)
  File "c:\pythoncode\houseprice\venv\lib\site-packages\joblib\_parallel_backends.py", line 208, in apply_async
    result = ImmediateResult(func)
  File "c:\pythoncode\houseprice\venv\lib\site-packages\joblib\_parallel_backends.py", line 597, in __init__
    self.results = batch()
  File "c:\pythoncode\houseprice\venv\lib\site-packages\joblib\parallel.py", line 288, in __call__
    return [func(*args, **kwargs)
  File "c:\pythoncode\houseprice\venv\lib\site-packages\joblib\parallel.py", line 288, in <listcomp>
    return [func(*args, **kwargs)
  File "c:\pythoncode\houseprice\venv\lib\site-packages\sklearn\utils\parallel.py", line 123, in __call__
    return self.function(*args, **kwargs)
  File "c:\pythoncode\houseprice\venv\lib\site-packages\sklearn\pipeline.py", line 876, in _transform_one
    res = transformer.transform(X)
  File "c:\pythoncode\houseprice\venv\lib\site-packages\sklearn\pipeline.py", line 658, in transform
    Xt = transform.transform(Xt)
  File "c:\pythoncode\houseprice\venv\lib\site-packages\sklearn\utils\_set_output.py", line 140, in wrapped
    data_to_wrap = f(self, X, *args, **kwargs)
  File "c:\pythoncode\houseprice\venv\lib\site-packages\sklearn\preprocessing\_encoders.py", line 1378, in transform
    X_int, X_mask = self._transform(
  File "c:\pythoncode\houseprice\venv\lib\site-packages\sklearn\preprocessing\_encoders.py", line 174, in _transform
    raise ValueError(msg)
ValueError: Found unknown categories [('Fair',)] in column 0 during transform

During handling of the above exception, another exception occurred:

Traceback (most recent call last):
  File "c:\pythoncode\houseprice\venv\lib\site-packages\flask\app.py", line 2528, in wsgi_app
    response = self.full_dispatch_request()
  File "c:\pythoncode\houseprice\venv\lib\site-packages\flask\app.py", line 1825, in full_dispatch_request
    rv = self.handle_user_exception(e)
  File "c:\pythoncode\houseprice\venv\lib\site-packages\flask\app.py", line 1823, in full_dispatch_request
    rv = self.dispatch_request()
  File "c:\pythoncode\houseprice\venv\lib\site-packages\flask\app.py", line 1799, in dispatch_request
    return self.ensure_sync(self.view_functions[rule.endpoint])(**view_args)
  File "application.py", line 55, in predict_datapoint
    pred=predict_pipeline.predict(final_df)
  File "C:\pythoncode\Flask_aws\src\pipelines\prediction_pipeline.py", line 30, in predict
    raise CustomException(e,sys)
src.exception.CustomException: Error occured in python script name [C:\pythoncode\Flask_aws\src\pipelines\prediction_pipeline.py] line number [22] error message [Found unknown categories [('Fair',)] in column 0 during transform]
[ 2023-04-19 07:36:44,013 ] 224 werkzeug - INFO - 127.0.0.1 - - [19/Apr/2023 07:36:44] "[35m[1mPOST /predict HTTP/1.1[0m" 500 -
[ 2023-04-19 07:37:30,193 ] 224 werkzeug - INFO - 127.0.0.1 - - [19/Apr/2023 07:37:30] "GET / HTTP/1.1" 200 -
[ 2023-04-19 07:37:33,558 ] 224 werkzeug - INFO - 127.0.0.1 - - [19/Apr/2023 07:37:33] "GET /predict HTTP/1.1" 200 -
[ 2023-04-19 07:37:42,647 ] 68 root - INFO - Dataframe Gathered
[ 2023-04-19 07:37:42,654 ] 29 root - INFO - Exception occured in prediction
[ 2023-04-19 07:37:42,654 ] 1744 application - ERROR - Exception on /predict [POST]
Traceback (most recent call last):
  File "C:\pythoncode\Flask_aws\src\pipelines\prediction_pipeline.py", line 22, in predict
    data_scaled=preprocessor.transform(features)
  File "c:\pythoncode\houseprice\venv\lib\site-packages\sklearn\utils\_set_output.py", line 140, in wrapped
    data_to_wrap = f(self, X, *args, **kwargs)
  File "c:\pythoncode\houseprice\venv\lib\site-packages\sklearn\compose\_column_transformer.py", line 800, in transform
    Xs = self._fit_transform(
  File "c:\pythoncode\houseprice\venv\lib\site-packages\sklearn\compose\_column_transformer.py", line 658, in _fit_transform
    return Parallel(n_jobs=self.n_jobs)(
  File "c:\pythoncode\houseprice\venv\lib\site-packages\sklearn\utils\parallel.py", line 63, in __call__
    return super().__call__(iterable_with_config)
  File "c:\pythoncode\houseprice\venv\lib\site-packages\joblib\parallel.py", line 1088, in __call__
    while self.dispatch_one_batch(iterator):
  File "c:\pythoncode\houseprice\venv\lib\site-packages\joblib\parallel.py", line 901, in dispatch_one_batch
    self._dispatch(tasks)
  File "c:\pythoncode\houseprice\venv\lib\site-packages\joblib\parallel.py", line 819, in _dispatch
    job = self._backend.apply_async(batch, callback=cb)
  File "c:\pythoncode\houseprice\venv\lib\site-packages\joblib\_parallel_backends.py", line 208, in apply_async
    result = ImmediateResult(func)
  File "c:\pythoncode\houseprice\venv\lib\site-packages\joblib\_parallel_backends.py", line 597, in __init__
    self.results = batch()
  File "c:\pythoncode\houseprice\venv\lib\site-packages\joblib\parallel.py", line 288, in __call__
    return [func(*args, **kwargs)
  File "c:\pythoncode\houseprice\venv\lib\site-packages\joblib\parallel.py", line 288, in <listcomp>
    return [func(*args, **kwargs)
  File "c:\pythoncode\houseprice\venv\lib\site-packages\sklearn\utils\parallel.py", line 123, in __call__
    return self.function(*args, **kwargs)
  File "c:\pythoncode\houseprice\venv\lib\site-packages\sklearn\pipeline.py", line 876, in _transform_one
    res = transformer.transform(X)
  File "c:\pythoncode\houseprice\venv\lib\site-packages\sklearn\pipeline.py", line 658, in transform
    Xt = transform.transform(Xt)
  File "c:\pythoncode\houseprice\venv\lib\site-packages\sklearn\utils\_set_output.py", line 140, in wrapped
    data_to_wrap = f(self, X, *args, **kwargs)
  File "c:\pythoncode\houseprice\venv\lib\site-packages\sklearn\preprocessing\_encoders.py", line 1378, in transform
    X_int, X_mask = self._transform(
  File "c:\pythoncode\houseprice\venv\lib\site-packages\sklearn\preprocessing\_encoders.py", line 174, in _transform
    raise ValueError(msg)
ValueError: Found unknown categories [('Fair',)] in column 0 during transform

During handling of the above exception, another exception occurred:

Traceback (most recent call last):
  File "c:\pythoncode\houseprice\venv\lib\site-packages\flask\app.py", line 2528, in wsgi_app
    response = self.full_dispatch_request()
  File "c:\pythoncode\houseprice\venv\lib\site-packages\flask\app.py", line 1825, in full_dispatch_request
    rv = self.handle_user_exception(e)
  File "c:\pythoncode\houseprice\venv\lib\site-packages\flask\app.py", line 1823, in full_dispatch_request
    rv = self.dispatch_request()
  File "c:\pythoncode\houseprice\venv\lib\site-packages\flask\app.py", line 1799, in dispatch_request
    return self.ensure_sync(self.view_functions[rule.endpoint])(**view_args)
  File "application.py", line 55, in predict_datapoint
    pred=predict_pipeline.predict(final_df)
  File "C:\pythoncode\Flask_aws\src\pipelines\prediction_pipeline.py", line 30, in predict
    raise CustomException(e,sys)
src.exception.CustomException: Error occured in python script name [C:\pythoncode\Flask_aws\src\pipelines\prediction_pipeline.py] line number [22] error message [Found unknown categories [('Fair',)] in column 0 during transform]
[ 2023-04-19 07:37:42,656 ] 224 werkzeug - INFO - 127.0.0.1 - - [19/Apr/2023 07:37:42] "[35m[1mPOST /predict HTTP/1.1[0m" 500 -
